Workbook

Sheet Assumptions
A4: MODEL ASSUMPTIONS
A5: Edit BLUE cells to change assumptions → Model & Charts update automatically
A7: CORE PRICING & PROGRAM RULES
A8: WAC Price | C8: 1649 | D8: Static for 12 months
A9: Pay No More Than | C9: 25 | D9: Patient max OOP
A10: Redemption Rate | C10: 0.8 | D10: Program redemption
A11: Medical Exception Pullthrough | C11: 0 | D11: Exception approval rate
A13: COST SHARING STRUCTURE
A14: Copay Mix % | C14: 0.8
A15: Coinsurance Mix % | C15: 0.2
A16: Copay Amount (Tier 3) | C16: 65
A17: Coinsurance Rate (Tier 3) | C17: 0.35
A18: Not Covered Buydown | C18: 1764.175 | D18: Buydown to $25 target
A20: COVERAGE UPTAKE FORECAST (% of Commercial Lives Covered)
A21: Higher coverage = Lower GTN (less not-covered buydown)
A22: Jan | C22: 0 | D22: =REPT("█",ROUND(C22*20,0))
A23: Feb | C23: 0 | D23: =REPT("█",ROUND(C23*20,0))
A24: Mar | C24: 0 | D24: =REPT("█",ROUND(C24*20,0))
A25: Apr | C25: 0.06 | D25: =REPT("█",ROUND(C25*20,0)) -> █
A26: May | C26: 0.11 | D26: =REPT("█",ROUND(C26*20,0)) -> ██
A27: Jun | C27: 0.29 | D27: =REPT("█",ROUND(C27*20,0)) -> ██████
A28: Jul | C28: 0.44 | D28: =REPT("█",ROUND(C28*20,0)) -> █████████
A29: Aug | C29: 0.52 | D29: =REPT("█",ROUND(C29*20,0)) -> ██████████
A30: Sep | C30: 0.58 | D30: =REPT("█",ROUND(C30*20,0)) -> ████████████
A31: Oct | C31: 0.58 | D31: =REPT("█",ROUND(C31*20,0)) -> ████████████
A32: Nov | C32: 0.58 | D32: =REPT("█",ROUND(C32*20,0)) -> ████████████
A33: Dec | C33: 0.58 | D33: =REPT("█",ROUND(C33*20,0)) -> ████████████
A35: DEDUCTIBLE MET (% by Month)
A36: Jan | C36: 0.03
A37: Feb | C37: 0.11
A38: Mar | C38: 0.2
A39: Apr | C39: 0.295
A40: May | C40: 0.395
A41: Jun | C41: 0.495
A42: Jul | C42: 0.595
A43: Aug | C43: 0.69
A44: Sep | C44: 0.785
A45: Oct | C45: 0.885
A46: Nov | C46: 0.949
A47: Dec | C47: 0.95
...

Sheet Model
D1: DETAILED AFFORDABILITY MODEL
E2: 2026
B3: Demand | C3: 1 | E3: Jan | F3: Feb | G3: Mar | H3: Apr | I3: May | J3: Jun | K3: Jul | L3: Aug | M3: Sep | N3: Oct | O3: Nov | P3: Dec | Q3: ANNUAL | R3: Notes
D4: TRx Forecast (Covered Commercial) | E4: =+IF($C$3=1,'Demand Models'!C10,'Demand Models'!C18) -> 0 | F4: =+IF($C$3=1,'Demand Models'!D10,'Demand Models'!D18) -> 50.23 | G4: =+IF($C$3=1,'Demand Models'!E10,'Demand Models'!E18) -> 83.78 | H4: =+IF($C$3=1,'Demand Models'!F10,'Demand Models'!F18) -> 131.82 | I4: =+IF($C$3=1,'Demand Models'!G10,'Demand Models'!G18) -> 300.71 | J4: =+IF($C$3=1,'Demand Models'!H10,'Demand Models'!H18) -> 667.02 | K4: =+IF($C$3=1,'Demand Models'!I10,'Demand Models'!I18) -> 1151.06 | L4: =+IF($C$3=1,'Demand Models'!J10,'Demand Models'!J18) -> 1505.31 | ... P4: =+IF($C$3=1,'Demand Models'!N10,'Demand Models'!N18) -> 3322.67 | Q4: =SUM(E4:P4) -> 14413.9
D5: TRx Forecast (Not Covered Commercial) | E5: =+IF($C$3=1,'Demand Models'!C11,'Demand Models'!C19) -> 0 | F5: =+IF($C$3=1,'Demand Models'!D11,'Demand Models'!D19) -> 64.58 | G5: =+IF($C$3=1,'Demand Models'!E11,'Demand Models'!E19) -> 104 | H5: =+IF($C$3=1,'Demand Models'!F11,'Demand Models'!F19) -> 158.18 | I5: =+IF($C$3=1,'Demand Models'!G11,'Demand Models'!G19) -> 199.99 | J5: =+IF($C$3=1,'Demand Models'!H11,'Demand Models'!H19) -> 192.77 | K5: =+IF($C$3=1,'Demand Models'!I11,'Demand Models'!I19) -> 194.47 | L5: =+IF($C$3=1,'Demand Models'!J11,'Demand Models'!J19) -> 249.11 | ... P5: =+IF($C$3=1,'Demand Models'!N11,'Demand Models'!N19) -> 359.88 | Q5: =SUM(E5:P5) -> 2345.46
D6: Coverage Uptake % | E6: =Assumptions!C22 -> 0 | F6: =Assumptions!C23 -> 0 | G6: =Assumptions!C24 -> 0 | H6: =Assumptions!C25 -> 0.06 | I6: =Assumptions!C26 -> 0.11 | J6: =Assumptions!C27 -> 0.29 | K6: =Assumptions!C28 -> 0.44 | L6: =Assumptions!C29 -> 0.52 | M6: =Assumptions!C30 -> 0.58 | N6: =Assumptions!C31 -> 0.58 | O6: =Assumptions!C32 -> 0.58 | P6: =Assumptions!C33 -> 0.58 | Q6: =AVERAGE(E6:P6) -> 0.31166667
D7: Payer Mix (Commercial) | E7: =Assumptions!C50 -> 0.96 | F7: =Assumptions!C51 -> 0.96 | G7: =Assumptions!C52 -> 0.96 | H7: =Assumptions!C53 -> 0.95 | I7: =Assumptions!C54 -> 0.95 | J7: =Assumptions!C55 -> 0.95 | K7: =Assumptions!C56 -> 0.9 | L7: =Assumptions!C57 -> 0.9 | M7: =Assumptions!C58 -> 0.9 | N7: =Assumptions!C59 -> 0.9 | O7: =Assumptions!C60 -> 0.9 | P7: =Assumptions!C61 -> 0.9
D8: % Covered Claims | E8: =E6+((1-E6)*Assumptions!$C$11) -> 0 | F8: =F6+((1-F6)*Assumptions!$C$11) -> 0 | G8: =G6+((1-G6)*Assumptions!$C$11) -> 0 | H8: =H6+((1-H6)*Assumptions!$C$11) -> 0.06 | I8: =I6+((1-I6)*Assumptions!$C$11) -> 0.11 | J8: =J6+((1-J6)*Assumptions!$C$11) -> 0.29 | K8: =K6+((1-K6)*Assumptions!$C$11) -> 0.44 | L8: =L6+((1-L6)*Assumptions!$C$11) -> 0.52 | ... P8: =P6+((1-P6)*Assumptions!$C$11) -> 0.58 | Q8: =AVERAGE(E8:P8) -> 0.31166667
D9: % Not Covered Claims | E9: =1-E8 -> 1 | F9: =1-F8 -> 1 | G9: =1-G8 -> 1 | H9: =1-H8 -> 0.94 | I9: =1-I8 -> 0.89 | J9: =1-J8 -> 0.71 | K9: =1-K8 -> 0.56 | L9: =1-L8 -> 0.48 | ... P9: =1-P8 -> 0.42 | Q9: =AVERAGE(E9:P9) -> 0.68833333
D10: % Met Deductible | E10: =Assumptions!C36 -> 0.03 | F10: =Assumptions!C37 -> 0.11 | G10: =Assumptions!C38 -> 0.2 | H10: =Assumptions!C39 -> 0.295 | I10: =Assumptions!C40 -> 0.395 | J10: =Assumptions!C41 -> 0.495 | K10: =Assumptions!C42 -> 0.595 | L10: =Assumptions!C43 -> 0.69 | M10: =Assumptions!C44 -> 0.785 | N10: =Assumptions!C45 -> 0.885 | O10: =Assumptions!C46 -> 0.949 | P10: =Assumptions!C47 -> 0.95
D11: % Copay Structure | E11: =Assumptions!$C$14 -> 0.8 | F11: =Assumptions!$C$14 -> 0.8 | G11: =Assumptions!$C$14 -> 0.8 | H11: =Assumptions!$C$14 -> 0.8 | I11: =Assumptions!$C$14 -> 0.8 | J11: =Assumptions!$C$14 -> 0.8 | K11: =Assumptions!$C$14 -> 0.8 | L11: =Assumptions!$C$14 -> 0.8 | ... P11: =Assumptions!$C$14 -> 0.8
D12: Copay Amount | E12: =Assumptions!$C$16 -> 65 | F12: =Assumptions!$C$16 -> 65 | G12: =Assumptions!$C$16 -> 65 | H12: =Assumptions!$C$16 -> 65 | I12: =Assumptions!$C$16 -> 65 | J12: =Assumptions!$C$16 -> 65 | K12: =Assumptions!$C$16 -> 65 | L12: =Assumptions!$C$16 -> 65 | ... P12: =Assumptions!$C$16 -> 65
D13: Copay Buydown | E13: =E12-Assumptions!$C$9 -> 40 | F13: =F12-Assumptions!$C$9 -> 40 | G13: =G12-Assumptions!$C$9 -> 40 | H13: =H12-Assumptions!$C$9 -> 40 | I13: =I12-Assumptions!$C$9 -> 40 | J13: =J12-Assumptions!$C$9 -> 40 | K13: =K12-Assumptions!$C$9 -> 40 | L13: =L12-Assumptions!$C$9 -> 40 | ... P13: =P12-Assumptions!$C$9 -> 40
D14: % Coinsurance Structure | E14: =Assumptions!$C$15 -> 0.2 | F14: =Assumptions!$C$15 -> 0.2 | G14: =Assumptions!$C$15 -> 0.2 | H14: =Assumptions!$C$15 -> 0.2 | I14: =Assumptions!$C$15 -> 0.2 | J14: =Assumptions!$C$15 -> 0.2 | K14: =Assumptions!$C$15 -> 0.2 | L14: =Assumptions!$C$15 -> 0.2 | ... P14: =Assumptions!$C$15 -> 0.2
D15: Coinsurance Amount | E15: =Assumptions!$C$17*Assumptions!$C$8 -> 577.15 | F15: =Assumptions!$C$17*Assumptions!$C$8 -> 577.15 | G15: =Assumptions!$C$17*Assumptions!$C$8 -> 577.15 | H15: =Assumptions!$C$17*Assumptions!$C$8 -> 577.15 | I15: =Assumptions!$C$17*Assumptions!$C$8 -> 577.15 | J15: =Assumptions!$C$17*Assumptions!$C$8 -> 577.15 | K15: =Assumptions!$C$17*Assumptions!$C$8 -> 577.15 | L15: =Assumptions!$C$17*Assumptions!$C$8 -> 577.15 | ... P15: =Assumptions!$C$17*Assumptions!$C$8 -> 577.15
D16: Coinsurance Buydown | E16: =E15-Assumptions!$C$9 -> 552.15 | F16: =F15-Assumptions!$C$9 -> 552.15 | G16: =G15-Assumptions!$C$9 -> 552.15 | H16: =H15-Assumptions!$C$9 -> 552.15 | I16: =I15-Assumptions!$C$9 -> 552.15 | J16: =J15-Assumptions!$C$9 -> 552.15 | K16: =K15-Assumptions!$C$9 -> 552.15 | L16: =L15-Assumptions!$C$9 -> 552.15 | ... P16: =P15-Assumptions!$C$9 -> 552.15
D17: Not Met Deductible Buydown | E17: =Assumptions!$C$8-Assumptions!$C$9 -> 1624 | F17: =Assumptions!$C$8-Assumptions!$C$9 -> 1624 | G17: =Assumptions!$C$8-Assumptions!$C$9 -> 1624 | H17: =Assumptions!$C$8-Assumptions!$C$9 -> 1624 | I17: =Assumptions!$C$8-Assumptions!$C$9 -> 1624 | J17: =Assumptions!$C$8-Assumptions!$C$9 -> 1624 | K17: =Assumptions!$C$8-Assumptions!$C$9 -> 1624 | L17: =Assumptions!$C$8-Assumptions!$C$9 -> 1624 | ... P17: =Assumptions!$C$8-Assumptions!$C$9 -> 1624
D18: Avg Covered Discount % | E18: =((E11*E13/Assumptions!$C$8)+(E14*E16/Assumptions!$C$8))*E10+((1-E10)*E17/Assumptions!$C$8) -> 0.95788532 | F18: =((F11*F13/Assumptions!$C$8)+(F14*F16/Assumptions!$C$8))*F10+((1-F10)*F17/Assumptions!$C$8) -> 0.88600807 | G18: =((G11*G13/Assumptions!$C$8)+(G14*G16/Assumptions!$C$8))*G10+((1-G10)*G17/Assumptions!$C$8) -> 0.80514615 | H18: =((H11*H13/Assumptions!$C$8)+(H14*H16/Assumptions!$C$8))*H10+((1-H10)*H17/Assumptions!$C$8) -> 0.7197919 | I18: =((I11*I13/Assumptions!$C$8)+(I14*I16/Assumptions!$C$8))*I10+((1-I10)*I17/Assumptions!$C$8) -> 0.62994533 | J18: =((J11*J13/Assumptions!$C$8)+(J14*J16/Assumptions!$C$8))*J10+((1-J10)*J17/Assumptions!$C$8) -> 0.54009876 | K18: =((K11*K13/Assumptions!$C$8)+(K14*K16/Assumptions!$C$8))*K10+((1-K10)*K17/Assumptions!$C$8) -> 0.45025218 | L18: =((L11*L13/Assumptions!$C$8)+(L14*L16/Assumptions!$C$8))*L10+((1-L10)*L17/Assumptions!$C$8) -> 0.36489794 | ... P18: =((P11*P13/Assumptions!$C$8)+(P14*P16/Assumptions!$C$8))*P10+((1-P10)*P17/Assumptions!$C$8) -> 0.13129685 | Q18: =AVERAGE(E18:P18) -> 0.50722989
D19: Avg Covered Benefit ($) | E19: =E18*Assumptions!$C$8 -> 1579.5529 | F19: =F18*Assumptions!$C$8 -> 1461.0273 | G19: =G18*Assumptions!$C$8 -> 1327.686 | H19: =H18*Assumptions!$C$8 -> 1186.9369 | I19: =I18*Assumptions!$C$8 -> 1038.7798 | J19: =J18*Assumptions!$C$8 -> 890.62285 | K19: =K18*Assumptions!$C$8 -> 742.46585 | L19: =L18*Assumptions!$C$8 -> 601.7167 | ... P19: =P18*Assumptions!$C$8 -> 216.5085 | Q19: =AVERAGE(E19:P19) -> 836.42208
D20: Not Covered Benefit ($) | E20: =Assumptions!$C$18 -> 1764.175 | F20: =Assumptions!$C$18 -> 1764.175 | G20: =Assumptions!$C$18 -> 1764.175 | H20: =Assumptions!$C$18 -> 1764.175 | I20: =Assumptions!$C$18 -> 1764.175 | J20: =Assumptions!$C$18 -> 1764.175 | K20: =Assumptions!$C$18 -> 1764.175 | L20: =Assumptions!$C$18 -> 1764.175 | ... P20: =Assumptions!$C$18 -> 1764.175
D21: Redemption Rate | E21: =Assumptions!$C$10 -> 0.8 | F21: =Assumptions!$C$10 -> 0.8 | G21: =Assumptions!$C$10 -> 0.8 | H21: =Assumptions!$C$10 -> 0.8 | I21: =Assumptions!$C$10 -> 0.8 | J21: =Assumptions!$C$10 -> 0.8 | K21: =Assumptions!$C$10 -> 0.8 | L21: =Assumptions!$C$10 -> 0.8 | ... P21: =Assumptions!$C$10 -> 0.8
D22: WAC Price | E22: =Assumptions!$C$8 -> 1649 | F22: =Assumptions!$C$8 -> 1649 | G22: =Assumptions!$C$8 -> 1649 | H22: =Assumptions!$C$8 -> 1649 | I22: =Assumptions!$C$8 -> 1649 | J22: =Assumptions!$C$8 -> 1649 | K22: =Assumptions!$C$8 -> 1649 | L22: =Assumptions!$C$8 -> 1649 | ... P22: =Assumptions!$C$8 -> 1649
D23: Covered Program Costs | E23: =E4*E21*E19 -> 0 | F23: =F4*F21*F19 -> 58709.921 | G23: =G4*G21*G19 -> 88986.826 | H23: =H4*H21*H19 -> 125169.61 | I23: =I4*I21*I19 -> 249897.19 | J23: =J4*J21*J19 -> 475250.6 | K23: =K4*K21*K19 -> 683698.19 | L23: =L4*L21*L19 -> 724616.13 | ... P23: =P4*P21*P19 -> 575509.04 | Q23: =SUM(E23:P23) -> 4800601.6
D24: Not Covered Program Costs | E24: =E5*E7*E21*E20 -> 0 | F24: =F5*F7*F21*F20 -> 87498.564 | G24: =G5*G7*G21*G20 -> 140908.19 | H24: =H5*H7*H21*H20 -> 212083.47 | I24: =I5*I7*I21*I20 -> 268141.19 | J24: =J5*J7*J21*J20 -> 258460.81 | K24: =K5*K7*K21*K20 -> 247016.96 | L24: =L5*L7*L21*L20 -> 316421.02 | ... P24: =P5*P7*P21*P20 -> 457121.74 | Q24: =SUM(E24:P24) -> 3032371
D25: TOTAL PROGRAM COSTS | E25: =E23+E24 -> 0 | F25: =F23+F24 -> 146208.48 | G25: =G23+G24 -> 229895.01 | H25: =H23+H24 -> 337253.09 | I25: =I23+I24 -> 518038.38 | J25: =J23+J24 -> 733711.41 | K25: =K23+K24 -> 930715.15 | L25: =L23+L24 -> 1041037.1 | ... P25: =P23+P24 -> 1032630.8 | Q25: =SUM(E25:P25) -> 7832972.6
D26: Gross Demand Sales | E26: =(E4+E5)*E22 -> 0 | F26: =(F4+F5)*F22 -> 189321.69 | G26: =(G4+G5)*G22 -> 309649.22 | H26: =(H4+H5)*H22 -> 478210 | I26: =(I4+I5)*I22 -> 825654.3 | J26: =(J4+J5)*J22 -> 1417793.7 | K26: =(K4+K5)*K22 -> 2218779 | L26: =(L4+L5)*L22 -> 2893038.6 | ... P26: =(P4+P5)*P22 -> 6072525 | Q26: =SUM(E26:P26) -> 27636185
D27: GTN % (Copay/Denial) | E27: =IFERROR(E25/E26,0) -> 0 | F27: =IFERROR(F25/F26,0) -> 0.7722754 | G27: =IFERROR(G25/G26,0) -> 0.74243692 | H27: =IFERROR(H25/H26,0) -> 0.70524055 | I27: =IFERROR(I25/I26,0) -> 0.62742771 | J27: =IFERROR(J25/J26,0) -> 0.51750224 | K27: =IFERROR(K25/K26,0) -> 0.41947178 | L27: =IFERROR(L25/L26,0) -> 0.35984212 | ... Q27: =IFERROR(Q25/Q26,0) -> 0.28343176
D28: Net Sales (After GTN) | E28: =E26-E25 -> 0 | F28: =F26-F25 -> 43113.205 | G28: =G26-G25 -> 79754.208 | H28: =H26-H25 -> 140956.91 | I28: =I26-I25 -> 307615.92 | J28: =J26-J25 -> 684082.3 | K28: =K26-K25 -> 1288063.8 | L28: =L26-L25 -> 1852001.4 | ... P28: =P26-P25 -> 5039894.2 | Q28: =SUM(E28:P28) -> 19803212
E29: 0 | F29: 43113.205 | G29: 79754.208 | H29: 140956.91 | I29: 307615.92 | J29: 684082.3 | K29: 1288063.8 | L29: 1852001.4 | M29: 2616524.4 | N29: 3497864.2 | O29: 4253341.4 | P29: 5039894.2 | Q29: =+SUM(E29:P29) -> 19803212
D30: Change | E30: =+E28-E29 -> 0 | F30: =+F28-F29 -> 0 | G30: =+G28-G29 -> 0 | H30: =+H28-H29 -> 0 | I30: =+I28-I29 -> 0 | J30: =+J28-J29 -> 0 | K30: =+K28-K29 -> 0 | L30: =+L28-L29 -> 0 | ... Q30: =+Q28-Q29 -> 0

Sheet Charts
A6: Month | B6: GTN % | C6: Coverage % | D6: Covered Cost | E6: Not Covered Cost | F6: Total Cost
A7: Jan | B7: =Model!E27 -> 0 | C7: =Model!E6 -> 0 | D7: =Model!E23 -> 0 | E7: =Model!E24 -> 0 | F7: =Model!E25 -> 0
A8: Feb | B8: =Model!F27 -> 0.7722754 | C8: =Model!F6 -> 0 | D8: =Model!F23 -> 58709.921 | E8: =Model!F24 -> 87498.564 | F8: =Model!F25 -> 146208.48
A9: Mar | B9: =Model!G27 -> 0.74243692 | C9: =Model!G6 -> 0 | D9: =Model!G23 -> 88986.826 | E9: =Model!G24 -> 140908.19 | F9: =Model!G25 -> 229895.01
A10: Apr | B10: =Model!H27 -> 0.70524055 | C10: =Model!H6 -> 0.06 | D10: =Model!H23 -> 125169.61 | E10: =Model!H24 -> 212083.47 | F10: =Model!H25 -> 337253.09
A11: May | B11: =Model!I27 -> 0.62742771 | C11: =Model!I6 -> 0.11 | D11: =Model!I23 -> 249897.19 | E11: =Model!I24 -> 268141.19 | F11: =Model!I25 -> 518038.38
A12: Jun | B12: =Model!J27 -> 0.51750224 | C12: =Model!J6 -> 0.29 | D12: =Model!J23 -> 475250.6 | E12: =Model!J24 -> 258460.81 | F12: =Model!J25 -> 733711.41
A13: Jul | B13: =Model!K27 -> 0.41947178 | C13: =Model!K6 -> 0.44 | D13: =Model!K23 -> 683698.19 | E13: =Model!K24 -> 247016.96 | F13: =Model!K25 -> 930715.15
A14: Aug | B14: =Model!L27 -> 0.35984212 | C14: =Model!L6 -> 0.52 | D14: =Model!L23 -> 724616.13 | E14: =Model!L24 -> 316421.02 | F14: =Model!L25 -> 1041037.1
A15: Sep | B15: =Model!M27 -> 0.30719078 | C15: =Model!M6 -> 0.58 | D15: =Model!M23 -> 715502.77 | E15: =Model!M24 -> 444661.01 | F15: =Model!M25 -> 1160163.8
A16: Oct | B16: =Model!N27 -> 0.19650781 | C16: =Model!N6 -> 0.58 | D16: =Model!N23 -> 612853.42 | E16: =Model!N24 -> 242609.35 | F16: =Model!N25 -> 855462.77
A17: Nov | B17: =Model!O27 -> 0.16620734 | C17: =Model!O6 -> 0.58 | D17: =Model!O23 -> 490407.9 | E17: =Model!O24 -> 357448.67 | F17: =Model!O25 -> 847856.57
A18: Dec | B18: =Model!P27 -> 0.17004966 | C18: =Model!P6 -> 0.58 | D18: =Model!P23 -> 575509.04 | E18: =Model!P24 -> 457121.74 | F18: =Model!P25 -> 1032630.8
A21: KEY METRICS
A22: Annual GTN % | C22: =Model!Q27 -> 0.28343176
A23: Total Program Costs | C23: =Model!Q25 -> 7832972.6
A24: Covered Costs | C24: =Model!Q23 -> 4800601.6
A25: Not Covered Costs | C25: =Model!Q24 -> 3032371
A26: Avg Coverage | C26: =AVERAGE(Model!E6:P6) -> 0.31166667

Sheet Accruals
A4: GTN ACCRUALS - INCOME STATEMENT METHOD
D7: 2026
E8: Jan | F8: Feb | G8: Mar | H8: Apr | I8: May | J8: Jun | K8: Jul | L8: Aug | M8: Sep | N8: Oct | O8: Nov | P8: Dec | Q8: ANNUAL
A10: EXFACTORY DEMAND
D11: ExFactory Units | E11: ='exFactory Demand Model'!G4 -> 474 | F11: ='exFactory Demand Model'!G5 -> 0 | G11: ='exFactory Demand Model'!G6 -> 478 | H11: ='exFactory Demand Model'!G7 -> 843 | I11: ='exFactory Demand Model'!G8 -> 1591 | J11: ='exFactory Demand Model'!G9 -> 1846.75 | K11: ='exFactory Demand Model'!G10 -> 4069.75 | L11: ='exFactory Demand Model'!G11 -> 3562.5 | M11: ='exFactory Demand Model'!G12 -> 5255.5 | N11: ='exFactory Demand Model'!G13 -> 4858.5 | O11: ='exFactory Demand Model'!G14 -> 6961.25 | P11: ='exFactory Demand Model'!G15 -> 6444.75 | Q11: =SUM(E11:P11) -> 36385
D12: WAC Price | E12: =Assumptions!$C$8 -> 1649 | F12: =Assumptions!$C$8 -> 1649 | G12: =Assumptions!$C$8 -> 1649 | H12: =Assumptions!$C$8 -> 1649 | I12: =Assumptions!$C$8 -> 1649 | J12: =Assumptions!$C$8 -> 1649 | K12: =Assumptions!$C$8 -> 1649 | L12: =Assumptions!$C$8 -> 1649 | ... P12: =Assumptions!$C$8 -> 1649
D13: ExFactory Gross Revenue | E13: =E11*E12 -> 781626 | F13: =F11*F12 -> 0 | G13: =G11*G12 -> 788222 | H13: =H11*H12 -> 1390107 | I13: =I11*I12 -> 2623559 | J13: =J11*J12 -> 3045290.8 | K13: =K11*K12 -> 6711017.8 | L13: =L11*L12 -> 5874562.5 | ... P13: =P11*P12 -> 10627393 | Q13: =SUM(E13:P13) -> 59998865
D15: Script Demand (Rx) | E15: 0 | F15: 130 | G15: 246 | H15: 445 | I15: 827 | J15: 1273 | K15: 2290 | L15: 3028 | M15: 3919 | N15: 4772 | O15: 5745 | P15: 6813 | Q15: =SUM(E15:P15) -> 29488
D16: MOH Target | E16: 0 | F16: 2 | G16: 2 | H16: 2 | I16: 2 | J16: 1.75 | K16: 1.75 | L16: 1.5 | M16: 1.5 | N16: 1.25 | O16: 1.25 | P16: 1
D17: Channel Inventory (EOM) | E17: =E15*E16 -> 0 | F17: =F15*F16 -> 260 | G17: =G15*G16 -> 492 | H17: =H15*H16 -> 890 | I17: =I15*I16 -> 1654 | J17: =J15*J16 -> 2227.75 | K17: =K15*K16 -> 4007.5 | L17: =L15*L16 -> 4542 | ... P17: =P15*P16 -> 6813
D18: ExFactory vs Rx Demand Ratio | E18: =IFERROR(E11/E15,0) -> 0 | F18: =IFERROR(F11/F15,0) -> 0 | G18: =IFERROR(G11/G15,0) -> 1.9430894 | H18: =IFERROR(H11/H15,0) -> 1.894382 | I18: =IFERROR(I11/I15,0) -> 1.923821 | J18: =IFERROR(J11/J15,0) -> 1.450707 | K18: =IFERROR(K11/K15,0) -> 1.7771834 | L18: =IFERROR(L11/L15,0) -> 1.1765192 | ... Q18: =IFERROR(Q11/Q15,0) -> 1.2338918
A20: GTN ACCRUAL (Income Statement Method)
D21: Rx Demand GTN % (from Model) | E21: =Model!E27 -> 0 | F21: =Model!F27 -> 0.7722754 | G21: =Model!G27 -> 0.74243692 | H21: =Model!H27 -> 0.70524055 | I21: =Model!I27 -> 0.62742771 | J21: =Model!J27 -> 0.51750224 | K21: =Model!K27 -> 0.41947178 | L21: =Model!L27 -> 0.35984212 | ... Q21: =Model!Q27 -> 0.28343176
D22: GTN Accrual (ExFactory × GTN%) | E22: =E13*E21 -> 0 | F22: =F13*F21 -> 0 | G22: =G13*G21 -> 585205.11 | H22: =H13*H21 -> 980359.83 | I22: =I13*I21 -> 1646093.6 | J22: =J13*J21 -> 1575944.8 | K22: =K13*K21 -> 2815082.5 | L22: =L13*L21 -> 2113915.1 | ... P22: =P13*P21 -> 1807184.5 | Q22: =SUM(E22:P22) -> 17668265
D23: Net Revenue (ExFactory - Accrual) | E23: =E13-E22 -> 781626 | F23: =F13-F22 -> 0 | G23: =G13-G22 -> 203016.89 | H23: =H13-H22 -> 409747.17 | I23: =I13-I22 -> 977465.4 | J23: =J13-J22 -> 1469346 | K23: =K13-K22 -> 3895935.2 | L23: =L13-L22 -> 3760647.4 | ... P23: =P13-P22 -> 8820208.3 | Q23: =SUM(E23:P23) -> 42330600
A26: ACCRUAL vs ACTUAL COMPARISON
D27: Actual GTN Costs (Rx-based) | E27: =Model!E25 -> 0 | F27: =Model!F25 -> 146208.48 | G27: =Model!G25 -> 229895.01 | H27: =Model!H25 -> 337253.09 | I27: =Model!I25 -> 518038.38 | J27: =Model!J25 -> 733711.41 | K27: =Model!K25 -> 930715.15 | L27: =Model!L25 -> 1041037.1 | ... P27: =Model!P25 -> 1032630.8 | Q27: =SUM(E27:P27) -> 7832972.6
D28: Accrued GTN (ExFactory-based) | E28: =E22 -> 0 | F28: =F22 -> 0 | G28: =G22 -> 585205.11 | H28: =H22 -> 980359.83 | I28: =I22 -> 1646093.6 | J28: =J22 -> 1575944.8 | K28: =K22 -> 2815082.5 | L28: =L22 -> 2113915.1 | ... P28: =P22 -> 1807184.5 | Q28: =SUM(E28:P28) -> 17668265
D29: Variance (Accrued - Actual) | E29: =E28-E27 -> 0 | F29: =F28-F27 -> -146208.48 | G29: =G28-G27 -> 355310.1 | H29: =H28-H27 -> 643106.75 | I29: =I28-I27 -> 1128055.2 | J29: =J28-J27 -> 842233.36 | K29: =K28-K27 -> 1884367.4 | L29: =L28-L27 -> 1072877.9 | ... P29: =P28-P27 -> 774553.7 | Q29: =SUM(E29:P29) -> 9835292.2
D30: Variance % | E30: =IFERROR(E29/E27,0) -> 0 | F30: =IFERROR(F29/F27,0) -> -1 | G30: =IFERROR(G29/G27,0) -> 1.545532 | H30: =IFERROR(H29/H27,0) -> 1.9068966 | I30: =IFERROR(I29/I27,0) -> 2.1775514 | J30: =IFERROR(J29/J27,0) -> 1.1479082 | K30: =IFERROR(K29/K27,0) -> 2.0246446 | L30: =IFERROR(L29/L27,0) -> 1.0305856 | ... Q30: =IFERROR(Q29/Q27,0) -> 1.255627
D31: Cumulative Variance | E31: =E29 -> 0 | F31: =E31+F29 -> -146208.48 | G31: =F31+G29 -> 209101.61 | H31: =G31+H29 -> 852208.36 | I31: =H31+I29 -> 1980263.6 | J31: =I31+J29 -> 2822496.9 | K31: =J31+K29 -> 4706864.3 | L31: =K31+L29 -> 5779742.2 | M31: =L31+M29 -> 7281791.8 | ... P31: =O31+P29 -> 9835292.2
A34: ACCRUAL RESERVE BALANCE (Balance Sheet)
D35: Beginning Balance | E35: 0 | F35: =E38 -> 0 | G35: =F38 -> -146208.48 | H35: =G38 -> 209101.61 | I35: =H38 -> 852208.36 | J35: =I38 -> 1980263.6 | K35: =J38 -> 2822496.9 | L35: =K38 -> 4706864.3 | M35: =L38 -> 5779742.2 | ... P35: =O38 -> 9060738.5
D36: + Accrual (I/S Charge) | E36: =E22 -> 0 | F36: =F22 -> 0 | G36: =G22 -> 585205.11 | H36: =H22 -> 980359.83 | I36: =I22 -> 1646093.6 | J36: =J22 -> 1575944.8 | K36: =K22 -> 2815082.5 | L36: =L22 -> 2113915.1 | ... P36: =P22 -> 1807184.5 | Q36: =SUM(E36:P36) -> 17668265
D37: - Actual Payments | E37: =E27 -> 0 | F37: =F27 -> 146208.48 | G37: =G27 -> 229895.01 | H37: =H27 -> 337253.09 | I37: =I27 -> 518038.38 | J37: =J27 -> 733711.41 | K37: =K27 -> 930715.15 | L37: =L27 -> 1041037.1 | ... P37: =P27 -> 1032630.8 | Q37: =SUM(E37:P37) -> 7832972.6
D38: Ending Balance | E38: =E35+E36-E37 -> 0 | F38: =F35+F36-F37 -> -146208.48 | G38: =G35+G36-G37 -> 209101.61 | H38: =H35+H36-H37 -> 852208.36 | I38: =I35+I36-I37 -> 1980263.6 | J38: =J35+J36-J37 -> 2822496.9 | K38: =K35+K36-K37 -> 4706864.3 | L38: =L35+L36-L37 -> 5779742.2 | ... P38: =P35+P36-P37 -> 9835292.2
A41: KEY METRICS FOR FINANCE
A42: Annual ExFactory Revenue | C42: =Q13 -> 59998865
A43: Annual GTN Accrual | C43: =Q22 -> 17668265
A44: Annual Net Revenue | C44: =Q23 -> 42330600
A45: Effective GTN Rate | C45: =Q22/Q13 -> 0.29447665
A46: Accrual vs Actual Variance | C46: =Q29 -> 9835292.2
A47: Year-End Reserve Balance | C47: =P38 -> 9835292.2
A50: Month | B50: Accrued | C50: Actual
A51: Jan | B51: =E28 -> 0 | C51: =E27 -> 0
A52: Feb | B52: =F28 -> 0 | C52: =F27 -> 146208.48
A53: Mar | B53: =G28 -> 585205.11 | C53: =G27 -> 229895.01
A54: Apr | B54: =H28 -> 980359.83 | C54: =H27 -> 337253.09
A55: May | B55: =I28 -> 1646093.6 | C55: =I27 -> 518038.38
A56: Jun | B56: =J28 -> 1575944.8 | C56: =J27 -> 733711.41
...

Sheet Scenarios
A4: SCENARIO ANALYSIS - MONTHLY VIEW
A5: For Finance Accruals: Edit PURPLE cells to model alternative coverage scenarios by month
A7: BASELINE (Current Model) | E7: Jan | F7: Feb | G7: Mar | H7: Apr | I7: May | J7: Jun | K7: Jul | L7: Aug | M7: Sep | N7: Oct | O7: Nov | P7: Dec | Q7: ANNUAL
D8: Coverage Uptake | E8: =Assumptions!C22 -> 0 | F8: =Assumptions!C23 -> 0 | G8: =Assumptions!C24 -> 0 | H8: =Assumptions!C25 -> 0.06 | I8: =Assumptions!C26 -> 0.11 | J8: =Assumptions!C27 -> 0.29 | K8: =Assumptions!C28 -> 0.44 | L8: =Assumptions!C29 -> 0.52 | M8: =Assumptions!C30 -> 0.58 | N8: =Assumptions!C31 -> 0.58 | O8: =Assumptions!C32 -> 0.58 | P8: =Assumptions!C33 -> 0.58 | Q8: =AVERAGE(E8:P8) -> 0.31166667
D9: GTN % | E9: =Model!E27 -> 0 | F9: =Model!F27 -> 0.7722754 | G9: =Model!G27 -> 0.74243692 | H9: =Model!H27 -> 0.70524055 | I9: =Model!I27 -> 0.62742771 | J9: =Model!J27 -> 0.51750224 | K9: =Model!K27 -> 0.41947178 | L9: =Model!L27 -> 0.35984212 | ... Q9: =Model!Q27 -> 0.28343176
D10: Program Costs | E10: =Model!E25 -> 0 | F10: =Model!F25 -> 146208.48 | G10: =Model!G25 -> 229895.01 | H10: =Model!H25 -> 337253.09 | I10: =Model!I25 -> 518038.38 | J10: =Model!J25 -> 733711.41 | K10: =Model!K25 -> 930715.15 | L10: =Model!L25 -> 1041037.1 | ... P10: =Model!P25 -> 1032630.8 | Q10: =SUM(E10:P10) -> 7832972.6
A13: SCENARIO (Edit Coverage Below) | E13: Jan | F13: Feb | G13: Mar | H13: Apr | I13: May | J13: Jun | K13: Jul | L13: Aug | M13: Sep | N13: Oct | O13: Nov | P13: Dec | Q13: ANNUAL
D14: Scenario Coverage | E14: 0 | F14: 0 | G14: 0 | H14: 0.06 | I14: 0.11 | J14: 0.29 | K14: 0.44 | L14: 0.52 | M14: 0.58 | N14: 0.58 | O14: 0.58 | P14: 0.58 | Q14: =AVERAGE(E14:P14) -> 0.31166667
D15: Scenario GTN % | E15: =MAX(0,E9*(1+(E8-E14)*1.5)) -> 0 | F15: =MAX(0,F9*(1+(F8-F14)*1.5)) -> 0.7722754 | G15: =MAX(0,G9*(1+(G8-G14)*1.5)) -> 0.74243692 | H15: =MAX(0,H9*(1+(H8-H14)*1.5)) -> 0.70524055 | I15: =MAX(0,I9*(1+(I8-I14)*1.5)) -> 0.62742771 | J15: =MAX(0,J9*(1+(J8-J14)*1.5)) -> 0.51750224 | K15: =MAX(0,K9*(1+(K8-K14)*1.5)) -> 0.41947178 | L15: =MAX(0,L9*(1+(L8-L14)*1.5)) -> 0.35984212 | ... P15: =MAX(0,P9*(1+(P8-P14)*1.5)) -> 0.17004966 | Q15: =IFERROR(SUM(E16:P16)/SUM(Model!E26:P26),0) -> 0.28343176
D16: Scenario Costs | E16: =E15*Model!E26 -> 0 | F16: =F15*Model!F26 -> 146208.48 | G16: =G15*Model!G26 -> 229895.01 | H16: =H15*Model!H26 -> 337253.09 | I16: =I15*Model!I26 -> 518038.38 | J16: =J15*Model!J26 -> 733711.41 | K16: =K15*Model!K26 -> 930715.15 | L16: =L15*Model!L26 -> 1041037.1 | ... P16: =P15*Model!P26 -> 1032630.8 | Q16: =SUM(E16:P16) -> 7832972.6
A19: DELTA (Scenario - Baseline) | E19: Jan | F19: Feb | G19: Mar | H19: Apr | I19: May | J19: Jun | K19: Jul | L19: Aug | M19: Sep | N19: Oct | O19: Nov | P19: Dec | Q19: ANNUAL
D20: Δ Coverage | E20: =E14-E8 -> 0 | F20: =F14-F8 -> 0 | G20: =G14-G8 -> 0 | H20: =H14-H8 -> 0 | I20: =I14-I8 -> 0 | J20: =J14-J8 -> 0 | K20: =K14-K8 -> 0 | L20: =L14-L8 -> 0 | ... P20: =P14-P8 -> 0 | Q20: =AVERAGE(E20:P20) -> 0
D21: Δ GTN % | E21: =E15-E9 -> 0 | F21: =F15-F9 -> 0 | G21: =G15-G9 -> 0 | H21: =H15-H9 -> 0 | I21: =I15-I9 -> 0 | J21: =J15-J9 -> 0 | K21: =K15-K9 -> 0 | L21: =L15-L9 -> 0 | ... Q21: =Q15-Q9 -> 0
D22: Δ Costs ($) | E22: =E16-E10 -> 0 | F22: =F16-F10 -> 0 | G22: =G16-G10 -> 0 | H22: =H16-H10 -> 0 | I22: =I16-I10 -> 0 | J22: =J16-J10 -> 0 | K22: =K16-K10 -> 0 | L22: =L16-L10 -> 0 | ... Q22: =Q16-Q10 -> 0
A25: Month | B25: Baseline GTN | C25: Scenario GTN | K25: HOW TO USE
A26: Jan | B26: =E9 -> 0 | C26: =E15 -> 0 | K26: 1. Edit PURPLE cells (row 14) to set scenario coverage by month
A27: Feb | B27: =F9 -> 0.7722754 | C27: =F15 -> 0.7722754 | K27: 2. Watch GTN % and Costs recalculate instantly
A28: Mar | B28: =G9 -> 0.74243692 | C28: =G15 -> 0.74243692 | K28: 3. DELTA section shows monthly variance for accruals
A29: Apr | B29: =H9 -> 0.70524055 | C29: =H15 -> 0.70524055 | K29: 4. Annual column shows full-year impact
A30: May | B30: =I9 -> 0.62742771 | C30: =I15 -> 0.62742771 | K30: 5. Negative Δ Costs = savings from higher coverage
A31: Jun | B31: =J9 -> 0.51750224 | C31: =J15 -> 0.51750224
A32: Jul | B32: =K9 -> 0.41947178 | C32: =K15 -> 0.41947178
A33: Aug | B33: =L9 -> 0.35984212 | C33: =L15 -> 0.35984212
A34: Sep | B34: =M9 -> 0.30719078 | C34: =M15 -> 0.30719078
A35: Oct | B35: =N9 -> 0.19650781 | C35: =N15 -> 0.19650781
A36: Nov | B36: =O9 -> 0.16620734 | C36: =O15 -> 0.16620734
A37: Dec | B37: =P9 -> 0.17004966 | C37: =P15 -> 0.17004966

Sheet Sensitivity
A4: SENSITIVITY ANALYSIS
A7: CURRENT MODEL BASELINE
A8: Annual GTN % | B8: =Model!Q27 -> 0.28343176
A9: Avg Coverage Uptake | B9: =AVERAGE(Assumptions!C22:C33) -> 0.31166667
A10: Medical Exception Rate | B10: =Assumptions!C11 -> 0
A13: COVERAGE UPTAKE IMPACT
A14: Coverage % | B14: Est. GTN % | C14: Change | D14: $ Impact
A15: 0.1 | B15: =$B$8*(1+($B$9-A15)*1.5) -> 0.37342135 | C15: =B15-$B$8 -> 0.089989585 | D15: =C15*Model!Q26 -> 2486968.8
A16: 0.2 | B16: =$B$8*(1+($B$9-A16)*1.5) -> 0.33090659 | C16: =B16-$B$8 -> 0.047474821 | D16: =C16*Model!Q26 -> 1312022.9
A17: 0.3 | B17: =$B$8*(1+($B$9-A17)*1.5) -> 0.28839182 | C17: =B17-$B$8 -> 0.0049600559 | D17: =C17*Model!Q26 -> 137077.02
A18: 0.4 | B18: =$B$8*(1+($B$9-A18)*1.5) -> 0.24587706 | C18: =B18-$B$8 -> -0.037554709 | D18: =C18*Model!Q26 -> -1037868.9
A19: 0.5 | B19: =$B$8*(1+($B$9-A19)*1.5) -> 0.20336229 | C19: =B19-$B$8 -> -0.080069474 | D19: =C19*Model!Q26 -> -2212814.8
A20: 0.6 | B20: =$B$8*(1+($B$9-A20)*1.5) -> 0.16084753 | C20: =B20-$B$8 -> -0.12258424 | D20: =C20*Model!Q26 -> -3387760.6
A21: 0.7 | B21: =$B$8*(1+($B$9-A21)*1.5) -> 0.11833276 | C21: =B21-$B$8 -> -0.165099 | D21: =C21*Model!Q26 -> -4562706.5
A22: 0.8 | B22: =$B$8*(1+($B$9-A22)*1.5) -> 0.075817997 | C22: =B22-$B$8 -> -0.20761377 | D22: =C22*Model!Q26 -> -5737652.4
A25: MEDICAL EXCEPTION IMPACT
A26: Exception % | B26: Est. GTN % | C26: Change | D26: $ Impact
A27: 0 | B27: =$B$8*(1-A27*0.5) -> 0.28343176 | C27: =B27-$B$8 -> 0 | D27: =C27*Model!Q26 -> 0
A28: 0.05 | B28: =$B$8*(1-A28*0.5) -> 0.27634597 | C28: =B28-$B$8 -> -0.0070857941 | D28: =C28*Model!Q26 -> -195824.31
A29: 0.1 | B29: =$B$8*(1-A29*0.5) -> 0.26926018 | C29: =B29-$B$8 -> -0.014171588 | D29: =C29*Model!Q26 -> -391648.63
A30: 0.15 | B30: =$B$8*(1-A30*0.5) -> 0.26217438 | C30: =B30-$B$8 -> -0.021257382 | D30: =C30*Model!Q26 -> -587472.94
A31: 0.2 | B31: =$B$8*(1-A31*0.5) -> 0.25508859 | C31: =B31-$B$8 -> -0.028343176 | D31: =C31*Model!Q26 -> -783297.26
A32: 0.25 | B32: =$B$8*(1-A32*0.5) -> 0.24800279 | C32: =B32-$B$8 -> -0.035428971 | D32: =C32*Model!Q26 -> -979121.57
A35: KEY INSIGHT
A36: Coverage has the HIGHEST impact. +10% coverage ≈ -15% GTN

Sheet exFactory Demand Model
C2: Beg of month channel balance | D2: Total Monthly Script Demand (Forecast) | E2: End of month channel balance | F2: MOH Assumption | G2: Total Monthly exFact Demand (Forecast)
B3: 46022 | C3: 0 | D3: 0 | E3: =+C3-D3+G3 -> 0 | F3: 0 | G3: 0
B4: =EOMONTH(B3+1,0) -> 46053 | C4: =E3 -> 0 | D4: 0 | E4: =+G4 -> 474 | F4: 0 | G4: 474
B5: =EOMONTH(B4+1,0) -> 46081 | C5: =+E4 -> 474 | D5: 130 | E5: =+F5*D5 -> 260 | F5: 2 | G5: =+IF(C5-D5>E5,0,E5-C5+D5) -> 0
B6: =EOMONTH(B5+1,0) -> 46112 | C6: =+E5 -> 260 | D6: 246 | E6: =+F6*D6 -> 492 | F6: 2 | G6: =+IF(C6-D6>E6,0,E6-C6+D6) -> 478
B7: =EOMONTH(B6+1,0) -> 46142 | C7: =+E6 -> 492 | D7: 445 | E7: =+F7*D7 -> 890 | F7: 2 | G7: =+IF(C7-D7>E7,0,E7-C7+D7) -> 843
B8: =EOMONTH(B7+1,0) -> 46173 | C8: =+E7 -> 890 | D8: 827 | E8: =+F8*D8 -> 1654 | F8: 2 | G8: =+IF(C8-D8>E8,0,E8-C8+D8) -> 1591
B9: =EOMONTH(B8+1,0) -> 46203 | C9: =+E8 -> 1654 | D9: 1273 | E9: =+F9*D9 -> 2227.75 | F9: 1.75 | G9: =+IF(C9-D9>E9,0,E9-C9+D9) -> 1846.75
B10: =EOMONTH(B9+1,0) -> 46234 | C10: =+E9 -> 2227.75 | D10: 2290 | E10: =+F10*D10 -> 4007.5 | F10: 1.75 | G10: =+IF(C10-D10>E10,0,E10-C10+D10) -> 4069.75
B11: =EOMONTH(B10+1,0) -> 46265 | C11: =+E10 -> 4007.5 | D11: 3028 | E11: =+F11*D11 -> 4542 | F11: 1.5 | G11: =+IF(C11-D11>E11,0,E11-C11+D11) -> 3562.5
B12: =EOMONTH(B11+1,0) -> 46295 | C12: =+E11 -> 4542 | D12: 3919 | E12: =+F12*D12 -> 5878.5 | F12: 1.5 | G12: =+IF(C12-D12>E12,0,E12-C12+D12) -> 5255.5
B13: =EOMONTH(B12+1,0) -> 46326 | C13: =+E12 -> 5878.5 | D13: 4772 | E13: =+F13*D13 -> 5965 | F13: 1.25 | G13: =+IF(C13-D13>E13,0,E13-C13+D13) -> 4858.5
B14: =EOMONTH(B13+1,0) -> 46356 | C14: =+E13 -> 5965 | D14: 5745 | E14: =+F14*D14 -> 7181.25 | F14: 1.25 | G14: =+IF(C14-D14>E14,0,E14-C14+D14) -> 6961.25
B15: =EOMONTH(B14+1,0) -> 46387 | C15: =+E14 -> 7181.25 | D15: 6813 | E15: =+F15*D15 -> 6813 | F15: 1 | G15: =+IF(C15-D15>E15,0,E15-C15+D15) -> 6444.75
B16: =EOMONTH(B15+1,0) -> 46418 | C16: =+E15 -> 6813 | D16: 8673 | E16: =+F16*D16 -> 8673 | F16: 1 | G16: =+IF(C16-D16>E16,0,E16-C16+D16) -> 10533

Sheet Demand Models
A4: Demand Scenarios
C7: Jan | D7: Feb | E7: Mar | F7: Apr | G7: May | H7: Jun | I7: Jul | J7: Aug | K7: Sep | L7: Oct | M7: Nov | N7: Dec | O7: Total
A8: 1 | B8: Original Base Model
B9: Total Commercial | C9: =+SUM(C10:C11) -> 0 | D9: =+SUM(D10:D11) -> 114.81 | E9: =+SUM(E10:E11) -> 187.78 | F9: =+SUM(F10:F11) -> 290 | G9: =+SUM(G10:G11) -> 500.7 | H9: =+SUM(H10:H11) -> 859.79 | I9: =+SUM(I10:I11) -> 1345.53 | J9: =+SUM(J10:J11) -> 1754.42 | ... N9: =+SUM(N10:N11) -> 3682.55 | O9: =+SUM(C9:N9) -> 16759.36
B10: TRx Forecast (Covered Commercial) | C10: 0 | D10: 50.23 | E10: 83.78 | F10: 131.82 | G10: 300.71 | H10: 667.02 | I10: 1151.06 | J10: 1505.31 | K10: 1940.22 | L10: 2448.98 | M10: 2812.1 | N10: 3322.67 | O10: =+SUM(C10:N10) -> 14413.9
B11: TRx Forecast (Not Covered Commercial) | C11: 0 | D11: 64.58 | E11: 104 | F11: 158.18 | G11: 199.99 | H11: 192.77 | I11: 194.47 | J11: 249.11 | K11: 350.07 | L11: 191 | M11: 281.41 | N11: 359.88 | O11: =+SUM(C11:N11) -> 2345.46
A13: 2 | B13: BOD Demand (November 2025 Meeting)
B14: Total Script Demand | C14: 0 | D14: 130 | E14: 246 | F14: 445 | G14: 827 | H14: 1273 | I14: 2290 | J14: 3028 | K14: 3919 | L14: 4772 | M14: 5745 | N14: 6813 | O14: =+SUM(C14:N14) -> 29488
B15: Total Commercial (%) | C15: =+Assumptions!C50 -> 0.96 | D15: =+Assumptions!C51 -> 0.96 | E15: =+Assumptions!C52 -> 0.96 | F15: =+Assumptions!C53 -> 0.95 | G15: =+Assumptions!C54 -> 0.95 | H15: =+Assumptions!C55 -> 0.95 | I15: =+Assumptions!C56 -> 0.9 | J15: =+Assumptions!C57 -> 0.9 | K15: =+Assumptions!C58 -> 0.9 | L15: =+Assumptions!C59 -> 0.9 | M15: =+Assumptions!C60 -> 0.9 | N15: =+Assumptions!C61 -> 0.9
B16: Total Commercial | C16: =+C14*C15 -> 0 | D16: =+D14*D15 -> 124.8 | E16: =+E14*E15 -> 236.16 | F16: =+F14*F15 -> 422.75 | G16: =+G14*G15 -> 785.65 | H16: =+H14*H15 -> 1209.35 | I16: =+I14*I15 -> 2061 | J16: =+J14*J15 -> 2725.2 | ... N16: =+N14*N15 -> 6131.7 | O16: =+SUM(C16:N16) -> 26689.01
B17: TRx Forecast (Covered Commercial %) | C17: =+Assumptions!C22 -> 0 | D17: =+Assumptions!C23 -> 0 | E17: =+Assumptions!C24 -> 0 | F17: =+Assumptions!C25 -> 0.06 | G17: =+Assumptions!C26 -> 0.11 | H17: =+Assumptions!C27 -> 0.29 | I17: =+Assumptions!C28 -> 0.44 | J17: =+Assumptions!C29 -> 0.52 | K17: =+Assumptions!C30 -> 0.58 | L17: =+Assumptions!C31 -> 0.58 | M17: =+Assumptions!C32 -> 0.58 | N17: =+Assumptions!C33 -> 0.58
B18: TRx Forecast (Covered Commercial) | C18: =+C16*C17 -> 0 | D18: =+D16*D17 -> 0 | E18: =+E16*E17 -> 0 | F18: =+F16*F17 -> 25.365 | G18: =+G16*G17 -> 86.4215 | H18: =+H16*H17 -> 350.7115 | I18: =+I16*I17 -> 906.84 | J18: =+J16*J17 -> 1417.104 | ... N18: =+N16*N17 -> 3556.386 | O18: =+SUM(C18:N18) -> 13878.42
B19: TRx Forecast (Not Covered Commercial) | C19: =+C16-C18 -> 0 | D19: =+D16-D18 -> 124.8 | E19: =+E16-E18 -> 236.16 | F19: =+F16-F18 -> 397.385 | G19: =+G16-G18 -> 699.2285 | H19: =+H16-H18 -> 858.6385 | I19: =+I16-I18 -> 1154.16 | J19: =+J16-J18 -> 1308.096 | ... N19: =+N16-N18 -> 2575.314 | O19: =+SUM(C19:N19) -> 12810.59
A24: Ex-Factory Demand Scenarios
C25: Jan | D25: Feb | E25: Mar | F25: Apr | G25: May | H25: Jun | I25: Jul | J25: Aug | K25: Sep | L25: Oct | M25: Nov | N25: Dec | O25: Total
B26: Beginning of Month Channel Balance
