Workbook

Sheet Assumptions
A4: MODEL ASSUMPTIONS
A5: Edit BLUE cells to change assumptions → Model & Charts update automatically
A7: CORE PRICING & PROGRAM RULES
A8: WAC Price | C8: 1649 | D8: Static for 12 months
A9: Pay No More Than | C9: 25 | D9: Patient max OOP
A10: Redemption Rate | C10: 0.8 | D10: Program redemption
A11: Medical Exception Pullthrough | C11: 0 | D11: Exception approval rate
A13: COST SHARING STRUCTURE
A14: Copay Mix % | C14: 0.8
A15: Coinsurance Mix % | C15: 0.2
A16: Copay Amount (Tier 3) | C16: 65
A17: Coinsurance Rate (Tier 3) | C17: 0.35
A18: Not Covered Buydown | C18: 1764.175 | D18: Buydown to $35 target
A20: COVERAGE UPTAKE FORECAST (% of Commercial Lives Covered)
A21: Higher coverage = Lower GTN (less not-covered buydown)
A22: Jan | C22: 0 | D22: =REPT("█",ROUND(C22*20,0))
A23: Feb | C23: 0 | D23: =REPT("█",ROUND(C23*20,0))
A24: Mar | C24: 0 | D24: =REPT("█",ROUND(C24*20,0))
A25: Apr | C25: 0.06 | D25: =REPT("█",ROUND(C25*20,0))
A26: May | C26: 0.11 | D26: =REPT("█",ROUND(C26*20,0))
A27: Jun | C27: 0.29 | D27: =REPT("█",ROUND(C27*20,0))
A28: Jul | C28: 0.44 | D28: =REPT("█",ROUND(C28*20,0))
A29: Aug | C29: 0.52 | D29: =REPT("█",ROUND(C29*20,0))
A30: Sep | C30: 0.58 | D30: =REPT("█",ROUND(C30*20,0))
A31: Oct | C31: 0.58 | D31: =REPT("█",ROUND(C31*20,0))
A32: Nov | C32: 0.58 | D32: =REPT("█",ROUND(C32*20,0))
A33: Dec | C33: 0.58 | D33: =REPT("█",ROUND(C33*20,0))
A35: DEDUCTIBLE MET (% by Month)
A36: Jan | C36: 0.03
A37: Feb | C37: 0.11
A38: Mar | C38: 0.2
A39: Apr | C39: 0.295
A40: May | C40: 0.395
A41: Jun | C41: 0.495
A42: Jul | C42: 0.595
A43: Aug | C43: 0.69
A44: Sep | C44: 0.785
A45: Oct | C45: 0.885
A46: Nov | C46: 0.949
A47: Dec | C47: 0.95
...

Sheet Model
D1: DETAILED AFFORDABILITY MODEL
E2: 2026
E3: Jan | F3: Feb | G3: Mar | H3: Apr | I3: May | J3: Jun | K3: Jul | L3: Aug | M3: Sep | N3: Oct | O3: Nov | P3: Dec | Q3: ANNUAL | R3: Notes
D4: TRx Forecast (Covered Commercial) | E4: 0 | F4: 50.23 | G4: 83.78 | H4: 131.82 | I4: 300.71 | J4: 667.02 | K4: 1151.06 | L4: 1505.31 | M4: 1940.22 | N4: 2448.98 | O4: 2812.1 | P4: 3322.67 | Q4: =SUM(E4:P4) | R4: From Demand Forecast
D5: TRx Forecast (Not Covered Commercial) | E5: 0 | F5: 64.58 | G5: 104 | H5: 158.18 | I5: 199.99 | J5: 192.77 | K5: 194.47 | L5: 249.11 | M5: 350.07 | N5: 191 | O5: 281.41 | P5: 359.88 | Q5: =SUM(E5:P5)
D6: Coverage Uptake % | E6: =Assumptions!C22 | F6: =Assumptions!C23 | G6: =Assumptions!C24 | H6: =Assumptions!C25 | I6: =Assumptions!C26 | J6: =Assumptions!C27 | K6: =Assumptions!C28 | L6: =Assumptions!C29 | M6: =Assumptions!C30 | N6: =Assumptions!C31 | O6: =Assumptions!C32 | P6: =Assumptions!C33 | Q6: =AVERAGE(E6:P6) | R6: KEY: From Coverage Tracker
D7: Payer Mix (Commercial) | E7: =Assumptions!C50 | F7: =Assumptions!C51 | G7: =Assumptions!C52 | H7: =Assumptions!C53 | I7: =Assumptions!C54 | J7: =Assumptions!C55 | K7: =Assumptions!C56 | L7: =Assumptions!C57 | M7: =Assumptions!C58 | N7: =Assumptions!C59 | O7: =Assumptions!C60 | P7: =Assumptions!C61
D8: % Covered Claims | E8: =E6+((1-E6)*Assumptions!$C$11) | F8: =F6+((1-F6)*Assumptions!$C$11) | G8: =G6+((1-G6)*Assumptions!$C$11) | H8: =H6+((1-H6)*Assumptions!$C$11) | I8: =I6+((1-I6)*Assumptions!$C$11) | J8: =J6+((1-J6)*Assumptions!$C$11) | K8: =K6+((1-K6)*Assumptions!$C$11) | L8: =L6+((1-L6)*Assumptions!$C$11) | ... P8: =P6+((1-P6)*Assumptions!$C$11) | Q8: =AVERAGE(E8:P8) | R8: Coverage + Exception Pullthrough
D9: % Not Covered Claims | E9: =1-E8 | F9: =1-F8 | G9: =1-G8 | H9: =1-H8 | I9: =1-I8 | J9: =1-J8 | K9: =1-K8 | L9: =1-L8 | ... P9: =1-P8 | Q9: =AVERAGE(E9:P9)
D10: % Met Deductible | E10: =Assumptions!C36 | F10: =Assumptions!C37 | G10: =Assumptions!C38 | H10: =Assumptions!C39 | I10: =Assumptions!C40 | J10: =Assumptions!C41 | K10: =Assumptions!C42 | L10: =Assumptions!C43 | M10: =Assumptions!C44 | N10: =Assumptions!C45 | O10: =Assumptions!C46 | P10: =Assumptions!C47
D11: % Copay Structure | E11: =Assumptions!$C$14 | F11: =Assumptions!$C$14 | G11: =Assumptions!$C$14 | H11: =Assumptions!$C$14 | I11: =Assumptions!$C$14 | J11: =Assumptions!$C$14 | K11: =Assumptions!$C$14 | L11: =Assumptions!$C$14 | ... P11: =Assumptions!$C$14
D12: Copay Amount | E12: =Assumptions!$C$16 | F12: =Assumptions!$C$16 | G12: =Assumptions!$C$16 | H12: =Assumptions!$C$16 | I12: =Assumptions!$C$16 | J12: =Assumptions!$C$16 | K12: =Assumptions!$C$16 | L12: =Assumptions!$C$16 | ... P12: =Assumptions!$C$16
D13: Copay Buydown | E13: =E12-Assumptions!$C$9 | F13: =F12-Assumptions!$C$9 | G13: =G12-Assumptions!$C$9 | H13: =H12-Assumptions!$C$9 | I13: =I12-Assumptions!$C$9 | J13: =J12-Assumptions!$C$9 | K13: =K12-Assumptions!$C$9 | L13: =L12-Assumptions!$C$9 | ... P13: =P12-Assumptions!$C$9
D14: % Coinsurance Structure | E14: =Assumptions!$C$15 | F14: =Assumptions!$C$15 | G14: =Assumptions!$C$15 | H14: =Assumptions!$C$15 | I14: =Assumptions!$C$15 | J14: =Assumptions!$C$15 | K14: =Assumptions!$C$15 | L14: =Assumptions!$C$15 | ... P14: =Assumptions!$C$15
D15: Coinsurance Amount | E15: =Assumptions!$C$17*Assumptions!$C$8 | F15: =Assumptions!$C$17*Assumptions!$C$8 | G15: =Assumptions!$C$17*Assumptions!$C$8 | H15: =Assumptions!$C$17*Assumptions!$C$8 | I15: =Assumptions!$C$17*Assumptions!$C$8 | J15: =Assumptions!$C$17*Assumptions!$C$8 | K15: =Assumptions!$C$17*Assumptions!$C$8 | L15: =Assumptions!$C$17*Assumptions!$C$8 | ... P15: =Assumptions!$C$17*Assumptions!$C$8
D16: Coinsurance Buydown | E16: =E15-Assumptions!$C$9 | F16: =F15-Assumptions!$C$9 | G16: =G15-Assumptions!$C$9 | H16: =H15-Assumptions!$C$9 | I16: =I15-Assumptions!$C$9 | J16: =J15-Assumptions!$C$9 | K16: =K15-Assumptions!$C$9 | L16: =L15-Assumptions!$C$9 | ... P16: =P15-Assumptions!$C$9
D17: Not Met Deductible Buydown | E17: =Assumptions!$C$8-Assumptions!$C$9 | F17: =Assumptions!$C$8-Assumptions!$C$9 | G17: =Assumptions!$C$8-Assumptions!$C$9 | H17: =Assumptions!$C$8-Assumptions!$C$9 | I17: =Assumptions!$C$8-Assumptions!$C$9 | J17: =Assumptions!$C$8-Assumptions!$C$9 | K17: =Assumptions!$C$8-Assumptions!$C$9 | L17: =Assumptions!$C$8-Assumptions!$C$9 | ... P17: =Assumptions!$C$8-Assumptions!$C$9
D18: Avg Covered Discount % | E18: =((E11*E13/Assumptions!$C$8)+(E14*E16/Assumptions!$C$8))*E10+((1-E10)*E17/Assumptions!$C$8) | F18: =((F11*F13/Assumptions!$C$8)+(F14*F16/Assumptions!$C$8))*F10+((1-F10)*F17/Assumptions!$C$8) | G18: =((G11*G13/Assumptions!$C$8)+(G14*G16/Assumptions!$C$8))*G10+((1-G10)*G17/Assumptions!$C$8) | H18: =((H11*H13/Assumptions!$C$8)+(H14*H16/Assumptions!$C$8))*H10+((1-H10)*H17/Assumptions!$C$8) | I18: =((I11*I13/Assumptions!$C$8)+(I14*I16/Assumptions!$C$8))*I10+((1-I10)*I17/Assumptions!$C$8) | J18: =((J11*J13/Assumptions!$C$8)+(J14*J16/Assumptions!$C$8))*J10+((1-J10)*J17/Assumptions!$C$8) | K18: =((K11*K13/Assumptions!$C$8)+(K14*K16/Assumptions!$C$8))*K10+((1-K10)*K17/Assumptions!$C$8) | L18: =((L11*L13/Assumptions!$C$8)+(L14*L16/Assumptions!$C$8))*L10+((1-L10)*L17/Assumptions!$C$8) | ... P18: =((P11*P13/Assumptions!$C$8)+(P14*P16/Assumptions!$C$8))*P10+((1-P10)*P17/Assumptions!$C$8) | Q18: =AVERAGE(E18:P18)
D19: Avg Covered Benefit ($) | E19: =E18*Assumptions!$C$8 | F19: =F18*Assumptions!$C$8 | G19: =G18*Assumptions!$C$8 | H19: =H18*Assumptions!$C$8 | I19: =I18*Assumptions!$C$8 | J19: =J18*Assumptions!$C$8 | K19: =K18*Assumptions!$C$8 | L19: =L18*Assumptions!$C$8 | ... P19: =P18*Assumptions!$C$8 | Q19: =AVERAGE(E19:P19)
D20: Not Covered Benefit ($) | E20: =Assumptions!$C$18 | F20: =Assumptions!$C$18 | G20: =Assumptions!$C$18 | H20: =Assumptions!$C$18 | I20: =Assumptions!$C$18 | J20: =Assumptions!$C$18 | K20: =Assumptions!$C$18 | L20: =Assumptions!$C$18 | ... P20: =Assumptions!$C$18 | R20: Buydown to $35
D21: Redemption Rate | E21: =Assumptions!$C$10 | F21: =Assumptions!$C$10 | G21: =Assumptions!$C$10 | H21: =Assumptions!$C$10 | I21: =Assumptions!$C$10 | J21: =Assumptions!$C$10 | K21: =Assumptions!$C$10 | L21: =Assumptions!$C$10 | ... P21: =Assumptions!$C$10
D22: WAC Price | E22: =Assumptions!$C$8 | F22: =Assumptions!$C$8 | G22: =Assumptions!$C$8 | H22: =Assumptions!$C$8 | I22: =Assumptions!$C$8 | J22: =Assumptions!$C$8 | K22: =Assumptions!$C$8 | L22: =Assumptions!$C$8 | ... P22: =Assumptions!$C$8
D23: Covered Program Costs | E23: =E4*E21*E19 | F23: =F4*F21*F19 | G23: =G4*G21*G19 | H23: =H4*H21*H19 | I23: =I4*I21*I19 | J23: =J4*J21*J19 | K23: =K4*K21*K19 | L23: =L4*L21*L19 | ... P23: =P4*P21*P19 | Q23: =SUM(E23:P23) | R23: TRx × Redemption × Benefit
D24: Not Covered Program Costs | E24: =E5*E7*E21*E20 | F24: =F5*F7*F21*F20 | G24: =G5*G7*G21*G20 | H24: =H5*H7*H21*H20 | I24: =I5*I7*I21*I20 | J24: =J5*J7*J21*J20 | K24: =K5*K7*K21*K20 | L24: =L5*L7*L21*L20 | ... P24: =P5*P7*P21*P20 | Q24: =SUM(E24:P24)
D25: TOTAL PROGRAM COSTS | E25: =E23+E24 | F25: =F23+F24 | G25: =G23+G24 | H25: =H23+H24 | I25: =I23+I24 | J25: =J23+J24 | K25: =K23+K24 | L25: =L23+L24 | ... P25: =P23+P24 | Q25: =SUM(E25:P25)
D26: Gross Demand Sales | E26: =(E4+E5)*E22 | F26: =(F4+F5)*F22 | G26: =(G4+G5)*G22 | H26: =(H4+H5)*H22 | I26: =(I4+I5)*I22 | J26: =(J4+J5)*J22 | K26: =(K4+K5)*K22 | L26: =(L4+L5)*L22 | ... P26: =(P4+P5)*P22 | Q26: =SUM(E26:P26)
D27: GTN % (Copay/Denial) | E27: =IFERROR(E25/E26,0) | F27: =IFERROR(F25/F26,0) | G27: =IFERROR(G25/G26,0) | H27: =IFERROR(H25/H26,0) | I27: =IFERROR(I25/I26,0) | J27: =IFERROR(J25/J26,0) | K27: =IFERROR(K25/K26,0) | L27: =IFERROR(L25/L26,0) | ... Q27: =IFERROR(Q25/Q26,0) | R27: KEY OUTPUT
D28: Net Sales (After GTN) | E28: =E26-E25 | F28: =F26-F25 | G28: =G26-G25 | H28: =H26-H25 | I28: =I26-I25 | J28: =J26-J25 | K28: =K26-K25 | L28: =L26-L25 | ... P28: =P26-P25 | Q28: =SUM(E28:P28)

Sheet Charts
A4: VISUAL DASHBOARD
A6: Chart Data (Hidden in production)
A7: Month | B7: GTN % | C7: Coverage % | D7: Covered Cost | E7: Not Covered Cost | F7: Total Cost
A8: Jan | B8: =Model!E27 | C8: =Model!E6 | D8: =Model!E23 | E8: =Model!E24 | F8: =Model!E25
A9: Feb | B9: =Model!F27 | C9: =Model!F6 | D9: =Model!F23 | E9: =Model!F24 | F9: =Model!F25
A10: Mar | B10: =Model!G27 | C10: =Model!G6 | D10: =Model!G23 | E10: =Model!G24 | F10: =Model!G25
A11: Apr | B11: =Model!H27 | C11: =Model!H6 | D11: =Model!H23 | E11: =Model!H24 | F11: =Model!H25
A12: May | B12: =Model!I27 | C12: =Model!I6 | D12: =Model!I23 | E12: =Model!I24 | F12: =Model!I25
A13: Jun | B13: =Model!J27 | C13: =Model!J6 | D13: =Model!J23 | E13: =Model!J24 | F13: =Model!J25
A14: Jul | B14: =Model!K27 | C14: =Model!K6 | D14: =Model!K23 | E14: =Model!K24 | F14: =Model!K25
A15: Aug | B15: =Model!L27 | C15: =Model!L6 | D15: =Model!L23 | E15: =Model!L24 | F15: =Model!L25
A16: Sep | B16: =Model!M27 | C16: =Model!M6 | D16: =Model!M23 | E16: =Model!M24 | F16: =Model!M25
A17: Oct | B17: =Model!N27 | C17: =Model!N6 | D17: =Model!N23 | E17: =Model!N24 | F17: =Model!N25
A18: Nov | B18: =Model!O27 | C18: =Model!O6 | D18: =Model!O23 | E18: =Model!O24 | F18: =Model!O25
A19: Dec | B19: =Model!P27 | C19: =Model!P6 | D19: =Model!P23 | E19: =Model!P24 | F19: =Model!P25
A22: KEY INSIGHTS
A23: Annual GTN %: | C23: =Model!Q27
A24: Total Program Costs: | C24: =Model!Q25
A25: Covered Costs: | C25: =Model!Q23
A26: Not Covered Costs: | C26: =Model!Q24
A27: Avg Coverage: | C27: =AVERAGE(Model!E6:P6)
A29: Coverage Impact:
A30: If coverage +10%: | C30: =Model!Q27*(1-0.08)
A31: If coverage -10%: | C31: =Model!Q27*(1+0.08)

Sheet Scenarios
A4: SCENARIO COMPARISON
A5: Toggle assumptions to see instant GTN impact
A7: SCENARIO INPUTS | C7: Current Model | D7: Low Coverage | E7: High Coverage | F7: High Exceptions
A8: Avg Coverage Uptake | C8: =AVERAGE(Assumptions!C22:C33) | D8: 0.2 | E8: 0.7 | F8: =C8
A9: Medical Exception Rate | C9: =Assumptions!C11 | D9: =C9 | E9: =C9 | F9: 0.15
A10: Redemption Rate | C10: =Assumptions!C10 | D10: =C10 | E10: =C10 | F10: =C10
A11: Pay No More Than | C11: =Assumptions!C9 | D11: =C11 | E11: =C11 | F11: =C11
A13: SCENARIO OUTPUTS | C13: Current Model | D13: Low Coverage | E13: High Coverage | F13: High Exceptions
A14: Estimated Annual GTN % | C14: =Model!Q27 | D14: =C14*(1+(C8-D8)*1.5) | E14: =C14*(1-(E8-C8)*1.2) | F14: =C14*(1-F9*0.5)
A15: vs Current Model | C15: - | D15: =D14-C14 | E15: =E14-C14 | F15: =F14-C14
A16: Est. Program Cost Impact | C16: =Model!Q25 | D16: =C16*(1+(C8-D8)*1.5) | E16: =C16*(1-(E8-C8)*1.2) | F16: =C16*(1-F9*0.5)
A17: $ Change vs Current | C17: - | D17: =D16-C16 | E17: =E16-C16 | F17: =F16-C16
A20: Scenario | B20: GTN %
A21: Current Model | B21: =C14
A22: Low Coverage | B22: =D14
A23: High Coverage | B23: =E14
A24: High Exceptions | B24: =F14
A27: HOW TO USE SCENARIOS
A28: 1. Current Model reflects your actual Assumptions tab settings
A29: 2. Edit the PURPLE cells (D8, E8, F9) to test different scenarios
A30: 3. Watch how GTN % and Program Costs change immediately
A31: 4. Low Coverage = More patients go through expensive Not Covered path
A32: 5. High Coverage = More patients have formulary access = lower buydown
A33: 6. High Exceptions = Medical exceptions approved = treated as covered

Sheet Sensitivity
A4: SENSITIVITY ANALYSIS
A5: How does GTN change when key assumptions shift?
A7: CURRENT MODEL BASELINE
A8: Annual GTN % | B8: =Model!Q27
A9: Avg Coverage Uptake | B9: =AVERAGE(Assumptions!C22:C33)
A10: Medical Exception Rate | B10: =Assumptions!C11
A11: Redemption Rate | B11: =Assumptions!C10
A14: COVERAGE UPTAKE IMPACT
A15: Coverage % | B15: Est. GTN % | C15: Change | D15: $ Impact | E15: Visual
A16: 0.1 | B16: =$B$8*(1+($B$9-A16)*1.5) | C16: =B16-$B$8 | D16: =C16*Model!Q26 | E16: =REPT("▼",MAX(0,ROUND(-C16*100,0)))&REPT("▲",MAX(0,ROUND(C16*100,0)))
A17: 0.2 | B17: =$B$8*(1+($B$9-A17)*1.5) | C17: =B17-$B$8 | D17: =C17*Model!Q26 | E17: =REPT("▼",MAX(0,ROUND(-C17*100,0)))&REPT("▲",MAX(0,ROUND(C17*100,0)))
A18: 0.3 | B18: =$B$8*(1+($B$9-A18)*1.5) | C18: =B18-$B$8 | D18: =C18*Model!Q26 | E18: =REPT("▼",MAX(0,ROUND(-C18*100,0)))&REPT("▲",MAX(0,ROUND(C18*100,0)))
A19: 0.4 | B19: =$B$8*(1+($B$9-A19)*1.5) | C19: =B19-$B$8 | D19: =C19*Model!Q26 | E19: =REPT("▼",MAX(0,ROUND(-C19*100,0)))&REPT("▲",MAX(0,ROUND(C19*100,0)))
A20: 0.5 | B20: =$B$8*(1+($B$9-A20)*1.5) | C20: =B20-$B$8 | D20: =C20*Model!Q26 | E20: =REPT("▼",MAX(0,ROUND(-C20*100,0)))&REPT("▲",MAX(0,ROUND(C20*100,0)))
A21: 0.6 | B21: =$B$8*(1+($B$9-A21)*1.5) | C21: =B21-$B$8 | D21: =C21*Model!Q26 | E21: =REPT("▼",MAX(0,ROUND(-C21*100,0)))&REPT("▲",MAX(0,ROUND(C21*100,0)))
A22: 0.7 | B22: =$B$8*(1+($B$9-A22)*1.5) | C22: =B22-$B$8 | D22: =C22*Model!Q26 | E22: =REPT("▼",MAX(0,ROUND(-C22*100,0)))&REPT("▲",MAX(0,ROUND(C22*100,0)))
A23: 0.8 | B23: =$B$8*(1+($B$9-A23)*1.5) | C23: =B23-$B$8 | D23: =C23*Model!Q26 | E23: =REPT("▼",MAX(0,ROUND(-C23*100,0)))&REPT("▲",MAX(0,ROUND(C23*100,0)))
A26: MEDICAL EXCEPTION IMPACT
A27: Exception % | B27: Est. GTN % | C27: Change | D27: $ Impact | E27: Visual
A28: 0 | B28: =$B$8*(1-A28*0.5) | C28: =B28-$B$8 | D28: =C28*Model!Q26 | E28: =REPT("▼",MAX(0,ROUND(-C28*100,0)))&REPT("▲",MAX(0,ROUND(C28*100,0)))
A29: 0.05 | B29: =$B$8*(1-A29*0.5) | C29: =B29-$B$8 | D29: =C29*Model!Q26 | E29: =REPT("▼",MAX(0,ROUND(-C29*100,0)))&REPT("▲",MAX(0,ROUND(C29*100,0)))
A30: 0.1 | B30: =$B$8*(1-A30*0.5) | C30: =B30-$B$8 | D30: =C30*Model!Q26 | E30: =REPT("▼",MAX(0,ROUND(-C30*100,0)))&REPT("▲",MAX(0,ROUND(C30*100,0)))
A31: 0.15 | B31: =$B$8*(1-A31*0.5) | C31: =B31-$B$8 | D31: =C31*Model!Q26 | E31: =REPT("▼",MAX(0,ROUND(-C31*100,0)))&REPT("▲",MAX(0,ROUND(C31*100,0)))
A32: 0.2 | B32: =$B$8*(1-A32*0.5) | C32: =B32-$B$8 | D32: =C32*Model!Q26 | E32: =REPT("▼",MAX(0,ROUND(-C32*100,0)))&REPT("▲",MAX(0,ROUND(C32*100,0)))
A33: 0.25 | B33: =$B$8*(1-A33*0.5) | C33: =B33-$B$8 | D33: =C33*Model!Q26 | E33: =REPT("▼",MAX(0,ROUND(-C33*100,0)))&REPT("▲",MAX(0,ROUND(C33*100,0)))
A36: KEY INSIGHT
A37: Coverage has the HIGHEST impact on GTN. Each 10% increase in coverage
A38: reduces GTN by ~15% because fewer patients need the expensive Not Covered buydown.

Sheet Dashboard
A4: EXECUTIVE SUMMARY
A6: ANNUAL GTN % | C6: TOTAL PROGRAM COST | E6: AVG COVERAGE
A7: =Model!Q27 | C7: =Model!Q25 | E7: =AVERAGE(Model!E6:P6)
